Workbook

Sheet 项目实施计划
A1: PIS 项目实施计划模板
A2: 项目名称 | B2: 【填写项目名称】 | C2: 项目经理 | E2: 计划开始日期 | F2: 【YYYY-MM-DD】 | G2: 目标上线日期 | H2: =K51 -> 0 | J2: 计划总工期 | K2: =IFERROR(MAX(K6:K60)-$F$2+1,"") | L2: 任务数 | M2: =COUNTA(D6:D60) -> 55 | N2: 关键里程碑 | O2: =COUNTIF(E6:E60,"里程碑") -> 7 | P2: 总体完成率 | Q2: 甘特图（按周，阶段按SOP / 任务按实际）
A3: 甲方（医院） | B3: 【填写医院/甲方单位】 | C3: 实施负责人 | E3: 项目类型 | F3: 【填写项目类型】 | G3: 计划验收日期 | H3: =K60 -> 0 | J3: 天 | L3: 项 | N3: 个 | P3: %
Q4: =IFERROR($F$2-WEEKDAY($F$2,2)+1,"") | R4: =IFERROR(Q4+7,"") | S4: =IFERROR(R4+7,"") | T4: =IFERROR(S4+7,"") | U4: =IFERROR(T4+7,"") | V4: =IFERROR(U4+7,"") | W4: =IFERROR(V4+7,"") | X4: =IFERROR(W4+7,"") | Y4: =IFERROR(X4+7,"") | ... AB4: =IFERROR(AA4+7,"")
A5: WBS | B5: SOP阶段 | C5: 工作线 | D5: 实际任务 | E5: 任务类型 | F5: 适用性 | G5: 主责 | H5: 协同 | I5: 计划开始 | J5: 工期(天) | K5: 计划完成 | L5: 前置任务 | M5: 状态 | N5: 完成率 | O5: 关键检查点/交付物 | P5: 当前问题/备注 | Q5: ="W"&COLUMN()-COLUMN($Q$5)+1 -> W1 | R5: ="W"&COLUMN()-COLUMN($Q$5)+1 -> W2 | S5: ="W"&COLUMN()-COLUMN($Q$5)+1 -> W3 | T5: ="W"&COLUMN()-COLUMN($Q$5)+1 -> W4 | U5: ="W"&COLUMN()-COLUMN($Q$5)+1 -> W5 | V5: ="W"&COLUMN()-COLUMN($Q$5)+1 -> W6 | W5: ="W"&COLUMN()-COLUMN($Q$5)+1 -> W7 | X5: ="W"&COLUMN()-COLUMN($Q$5)+1 -> W8 | ... AB5: ="W"&COLUMN()-COLUMN($Q$5)+1 -> W12
A6: 1.1 | B6: 事前准备 | C6: 项目准备 | D6: 销售/项目资料移交 | E6: 任务 | F6: 必做 | G6: 项目经理 | H6: 销售/实施 | M6: 未开始 | N6: 0 | O6: 项目资料已完整移交 | Q6: =IFERROR(IF(AND(Q$4<=$K6,Q$4+6>=$I6),"■",""),"") | R6: =IFERROR(IF(AND(R$4<=$K6,R$4+6>=$I6),"■",""),"") | S6: =IFERROR(IF(AND(S$4<=$K6,S$4+6>=$I6),"■",""),"") | T6: =IFERROR(IF(AND(T$4<=$K6,T$4+6>=$I6),"■",""),"") | U6: =IFERROR(IF(AND(U$4<=$K6,U$4+6>=$I6),"■",""),"") | V6: =IFERROR(IF(AND(V$4<=$K6,V$4+6>=$I6),"■",""),"") | W6: =IFERROR(IF(AND(W$4<=$K6,W$4+6>=$I6),"■",""),"") | X6: =IFERROR(IF(AND(X$4<=$K6,X$4+6>=$I6),"■",""),"") | ... AB6: =IFERROR(IF(AND(AB$4<=$K6,AB$4+6>=$I6),"■",""),"")
A7: 1.2 | D7: 项目基础信息核对 | E7: 任务 | F7: 必做 | G7: 项目经理 | H7: 实施/销售 | L7: 1.1 | M7: 未开始 | N7: 0 | O7: 范围、现用系统、关键节点明确 | Q7: =IFERROR(IF(AND(Q$4<=$K7,Q$4+6>=$I7),"■",""),"") | R7: =IFERROR(IF(AND(R$4<=$K7,R$4+6>=$I7),"■",""),"") | S7: =IFERROR(IF(AND(S$4<=$K7,S$4+6>=$I7),"■",""),"") | T7: =IFERROR(IF(AND(T$4<=$K7,T$4+6>=$I7),"■",""),"") | U7: =IFERROR(IF(AND(U$4<=$K7,U$4+6>=$I7),"■",""),"") | V7: =IFERROR(IF(AND(V$4<=$K7,V$4+6>=$I7),"■",""),"") | W7: =IFERROR(IF(AND(W$4<=$K7,W$4+6>=$I7),"■",""),"") | X7: =IFERROR(IF(AND(X$4<=$K7,X$4+6>=$I7),"■",""),"") | ... AB7: =IFERROR(IF(AND(AB$4<=$K7,AB$4+6>=$I7),"■",""),"")
A8: 1.3 | D8: 项目调研 | E8: 任务 | F8: 必做 | G8: 产品经理 | H8: 实施 | L8: 1.1 | M8: 未开始 | N8: 0 | O8: 项目调研报告
A9: 1.4 | C9: 接口准备 | D9: 软硬件接口清单/文档/第三方人员核查 | E9: 任务 | F9: 必做 | G9: 项目经理 | H9: 实施/销售/第三方 | L9: 1.1 | M9: 未开始 | N9: 0 | O9: 接口清单、文档版本、联调人明确 | Q9: =IFERROR(IF(AND(Q$4<=$K9,Q$4+6>=$I9),"■",""),"") | R9: =IFERROR(IF(AND(R$4<=$K9,R$4+6>=$I9),"■",""),"") | S9: =IFERROR(IF(AND(S$4<=$K9,S$4+6>=$I9),"■",""),"") | T9: =IFERROR(IF(AND(T$4<=$K9,T$4+6>=$I9),"■",""),"") | U9: =IFERROR(IF(AND(U$4<=$K9,U$4+6>=$I9),"■",""),"") | V9: =IFERROR(IF(AND(V$4<=$K9,V$4+6>=$I9),"■",""),"") | W9: =IFERROR(IF(AND(W$4<=$K9,W$4+6>=$I9),"■",""),"") | X9: =IFERROR(IF(AND(X$4<=$K9,X$4+6>=$I9),"■",""),"") | ... AB9: =IFERROR(IF(AND(AB$4<=$K9,AB$4+6>=$I9),"■",""),"")
A10: 1.5 | C10: 环境准备 | D10: 服务器/网络/账号/测试数据条件核查 | E10: 任务 | F10: 必做 | G10: 项目经理 | H10: 运维/实施/信息科 | L10: 1.1 | M10: 未开始 | N10: 0 | O10: 环境及资源前置条件明确 | Q10: =IFERROR(IF(AND(Q$4<=$K10,Q$4+6>=$I10),"■",""),"") | R10: =IFERROR(IF(AND(R$4<=$K10,R$4+6>=$I10),"■",""),"") | S10: =IFERROR(IF(AND(S$4<=$K10,S$4+6>=$I10),"■",""),"") | T10: =IFERROR(IF(AND(T$4<=$K10,T$4+6>=$I10),"■",""),"") | U10: =IFERROR(IF(AND(U$4<=$K10,U$4+6>=$I10),"■",""),"") | V10: =IFERROR(IF(AND(V$4<=$K10,V$4+6>=$I10),"■",""),"") | W10: =IFERROR(IF(AND(W$4<=$K10,W$4+6>=$I10),"■",""),"") | X10: =IFERROR(IF(AND(X$4<=$K10,X$4+6>=$I10),"■",""),"") | ... AB10: =IFERROR(IF(AND(AB$4<=$K10,AB$4+6>=$I10),"■",""),"")
A11: 1.6 | C11: 项目管理 | D11: 项目实施计划编制 | E11: 任务 | F11: 必做 | G11: 项目经理 | H11: 实施/运维 | L11: 1.2 | M11: 未开始 | N11: 0 | O11: 项目计划及关键里程碑 | Q11: =IFERROR(IF(AND(Q$4<=$K11,Q$4+6>=$I11),"■",""),"") | R11: =IFERROR(IF(AND(R$4<=$K11,R$4+6>=$I11),"■",""),"") | S11: =IFERROR(IF(AND(S$4<=$K11,S$4+6>=$I11),"■",""),"") | T11: =IFERROR(IF(AND(T$4<=$K11,T$4+6>=$I11),"■",""),"") | U11: =IFERROR(IF(AND(U$4<=$K11,U$4+6>=$I11),"■",""),"") | V11: =IFERROR(IF(AND(V$4<=$K11,V$4+6>=$I11),"■",""),"") | W11: =IFERROR(IF(AND(W$4<=$K11,W$4+6>=$I11),"■",""),"") | X11: =IFERROR(IF(AND(X$4<=$K11,X$4+6>=$I11),"■",""),"") | ... AB11: =IFERROR(IF(AND(AB$4<=$K11,AB$4+6>=$I11),"■",""),"")
A12: 1.7 | D12: 进场准入评审 | E12: 里程碑 | F12: 必做 | G12: 项目经理 | H12: 交付负责人 | L12: 1.3,1.4,1.5,1.6 | M12: 未开始 | N12: 0 | O12: 具备进场条件/红线项关闭 | Q12: =IFERROR(IF(AND(Q$4<=$K12,Q$4+6>=$I12),"■",""),"") | R12: =IFERROR(IF(AND(R$4<=$K12,R$4+6>=$I12),"■",""),"") | S12: =IFERROR(IF(AND(S$4<=$K12,S$4+6>=$I12),"■",""),"") | T12: =IFERROR(IF(AND(T$4<=$K12,T$4+6>=$I12),"■",""),"") | U12: =IFERROR(IF(AND(U$4<=$K12,U$4+6>=$I12),"■",""),"") | V12: =IFERROR(IF(AND(V$4<=$K12,V$4+6>=$I12),"■",""),"") | W12: =IFERROR(IF(AND(W$4<=$K12,W$4+6>=$I12),"■",""),"") | X12: =IFERROR(IF(AND(X$4<=$K12,X$4+6>=$I12),"■",""),"") | ... AB12: =IFERROR(IF(AND(AB$4<=$K12,AB$4+6>=$I12),"■",""),"")
A13: 1.8 | D13: 项目启动会 | E13: 里程碑 | F13: 必做 | G13: 项目经理 | H13: 甲方项目负责人/实施/销售 | L13: 1.7 | M13: 未开始 | N13: 0 | O13: 项目启动会议纪要 | Q13: =IFERROR(IF(AND(Q$4<=$K13,Q$4+6>=$I13),"■",""),"") | R13: =IFERROR(IF(AND(R$4<=$K13,R$4+6>=$I13),"■",""),"") | S13: =IFERROR(IF(AND(S$4<=$K13,S$4+6>=$I13),"■",""),"") | T13: =IFERROR(IF(AND(T$4<=$K13,T$4+6>=$I13),"■",""),"") | U13: =IFERROR(IF(AND(U$4<=$K13,U$4+6>=$I13),"■",""),"") | V13: =IFERROR(IF(AND(V$4<=$K13,V$4+6>=$I13),"■",""),"") | W13: =IFERROR(IF(AND(W$4<=$K13,W$4+6>=$I13),"■",""),"") | X13: =IFERROR(IF(AND(X$4<=$K13,X$4+6>=$I13),"■",""),"") | ... AB13: =IFERROR(IF(AND(AB$4<=$K13,AB$4+6>=$I13),"■",""),"")
A14: 2.1 | B14: 实施执行 | C14: 环境与部署 | D14: 测试/生产环境部署 | E14: 任务 | F14: 必做 | G14: 运维 | H14: 实施 | L14: 1.8 | M14: 未开始 | N14: 0 | O14: 系统可访问、服务可启动 | Q14: =IFERROR(IF(AND(Q$4<=$K14,Q$4+6>=$I14),"■",""),"") | R14: =IFERROR(IF(AND(R$4<=$K14,R$4+6>=$I14),"■",""),"") | S14: =IFERROR(IF(AND(S$4<=$K14,S$4+6>=$I14),"■",""),"") | T14: =IFERROR(IF(AND(T$4<=$K14,T$4+6>=$I14),"■",""),"") | U14: =IFERROR(IF(AND(U$4<=$K14,U$4+6>=$I14),"■",""),"") | V14: =IFERROR(IF(AND(V$4<=$K14,V$4+6>=$I14),"■",""),"") | W14: =IFERROR(IF(AND(W$4<=$K14,W$4+6>=$I14),"■",""),"") | X14: =IFERROR(IF(AND(X$4<=$K14,X$4+6>=$I14),"■",""),"") | ... AB14: =IFERROR(IF(AND(AB$4<=$K14,AB$4+6>=$I14),"■",""),"")
A15: 2.2 | D15: 端口/防火墙/账号权限验证 | E15: 任务 | F15: 必做 | G15: 运维 | H15: 实施/信息科 | L15: 2.1 | M15: 未开始 | N15: 0 | O15: 网络及账号权限可用 | Q15: =IFERROR(IF(AND(Q$4<=$K15,Q$4+6>=$I15),"■",""),"") | R15: =IFERROR(IF(AND(R$4<=$K15,R$4+6>=$I15),"■",""),"") | S15: =IFERROR(IF(AND(S$4<=$K15,S$4+6>=$I15),"■",""),"") | T15: =IFERROR(IF(AND(T$4<=$K15,T$4+6>=$I15),"■",""),"") | U15: =IFERROR(IF(AND(U$4<=$K15,U$4+6>=$I15),"■",""),"") | V15: =IFERROR(IF(AND(V$4<=$K15,V$4+6>=$I15),"■",""),"") | W15: =IFERROR(IF(AND(W$4<=$K15,W$4+6>=$I15),"■",""),"") | X15: =IFERROR(IF(AND(X$4<=$K15,X$4+6>=$I15),"■",""),"") | ... AB15: =IFERROR(IF(AND(AB$4<=$K15,AB$4+6>=$I15),"■",""),"")
A16: 2.3 | D16: 终端/打印机/条码设备确认 | E16: 任务 | F16: 必做 | G16: 实施 | H16: 运维/甲方 | L16: 2.1 | M16: 未开始 | N16: 0 | O16: 关键终端与外设可用 | Q16: =IFERROR(IF(AND(Q$4<=$K16,Q$4+6>=$I16),"■",""),"") | R16: =IFERROR(IF(AND(R$4<=$K16,R$4+6>=$I16),"■",""),"") | S16: =IFERROR(IF(AND(S$4<=$K16,S$4+6>=$I16),"■",""),"") | T16: =IFERROR(IF(AND(T$4<=$K16,T$4+6>=$I16),"■",""),"") | U16: =IFERROR(IF(AND(U$4<=$K16,U$4+6>=$I16),"■",""),"") | V16: =IFERROR(IF(AND(V$4<=$K16,V$4+6>=$I16),"■",""),"") | W16: =IFERROR(IF(AND(W$4<=$K16,W$4+6>=$I16),"■",""),"") | X16: =IFERROR(IF(AND(X$4<=$K16,X$4+6>=$I16),"■",""),"") | ... AB16: =IFERROR(IF(AND(AB$4<=$K16,AB$4+6>=$I16),"■",""),"")
A17: 2.4 | C17: 基础数据 | D17: 组织/科室/人员/权限资料收集 | E17: 任务 | F17: 必做 | G17: 实施 | H17: 甲方 | L17: 1.8 | M17: 未开始 | N17: 0 | O17: 基础人员及权限资料齐全 | Q17: =IFERROR(IF(AND(Q$4<=$K17,Q$4+6>=$I17),"■",""),"") | R17: =IFERROR(IF(AND(R$4<=$K17,R$4+6>=$I17),"■",""),"") | S17: =IFERROR(IF(AND(S$4<=$K17,S$4+6>=$I17),"■",""),"") | T17: =IFERROR(IF(AND(T$4<=$K17,T$4+6>=$I17),"■",""),"") | U17: =IFERROR(IF(AND(U$4<=$K17,U$4+6>=$I17),"■",""),"") | V17: =IFERROR(IF(AND(V$4<=$K17,V$4+6>=$I17),"■",""),"") | W17: =IFERROR(IF(AND(W$4<=$K17,W$4+6>=$I17),"■",""),"") | X17: =IFERROR(IF(AND(X$4<=$K17,X$4+6>=$I17),"■",""),"") | ... AB17: =IFERROR(IF(AND(AB$4<=$K17,AB$4+6>=$I17),"■",""),"")
A18: 2.5 | D18: 基础字典/业务类型资料收集 | E18: 任务 | F18: 必做 | G18: 实施 | H18: 甲方 | L18: 1.8 | M18: 未开始 | N18: 0 | O18: 基础字典清单 | Q18: =IFERROR(IF(AND(Q$4<=$K18,Q$4+6>=$I18),"■",""),"") | R18: =IFERROR(IF(AND(R$4<=$K18,R$4+6>=$I18),"■",""),"") | S18: =IFERROR(IF(AND(S$4<=$K18,S$4+6>=$I18),"■",""),"") | T18: =IFERROR(IF(AND(T$4<=$K18,T$4+6>=$I18),"■",""),"") | U18: =IFERROR(IF(AND(U$4<=$K18,U$4+6>=$I18),"■",""),"") | V18: =IFERROR(IF(AND(V$4<=$K18,V$4+6>=$I18),"■",""),"") | W18: =IFERROR(IF(AND(W$4<=$K18,W$4+6>=$I18),"■",""),"") | X18: =IFERROR(IF(AND(X$4<=$K18,X$4+6>=$I18),"■",""),"") | ... AB18: =IFERROR(IF(AND(AB$4<=$K18,AB$4+6>=$I18),"■",""),"")
A19: 2.6 | D19: 基础数据导入与核对 | E19: 任务 | F19: 必做 | G19: 实施 | H19: 甲方 | L19: 2.1,2.4,2.5 | M19: 未开始 | N19: 0 | O19: 基础数据导入完成并核对 | Q19: =IFERROR(IF(AND(Q$4<=$K19,Q$4+6>=$I19),"■",""),"") | R19: =IFERROR(IF(AND(R$4<=$K19,R$4+6>=$I19),"■",""),"") | S19: =IFERROR(IF(AND(S$4<=$K19,S$4+6>=$I19),"■",""),"") | T19: =IFERROR(IF(AND(T$4<=$K19,T$4+6>=$I19),"■",""),"") | U19: =IFERROR(IF(AND(U$4<=$K19,U$4+6>=$I19),"■",""),"") | V19: =IFERROR(IF(AND(V$4<=$K19,V$4+6>=$I19),"■",""),"") | W19: =IFERROR(IF(AND(W$4<=$K19,W$4+6>=$I19),"■",""),"") | X19: =IFERROR(IF(AND(X$4<=$K19,X$4+6>=$I19),"■",""),"") | ... AB19: =IFERROR(IF(AND(AB$4<=$K19,AB$4+6>=$I19),"■",""),"")
A20: 2.7 | C20: 系统配置 | D20: 业务流程/编号规则确认 | E20: 任务 | F20: 必做 | G20: 实施 | H20: 项目经理/甲方 | L20: 1.8 | M20: 未开始 | N20: 0 | O20: 业务流程和编号规则确认 | Q20: =IFERROR(IF(AND(Q$4<=$K20,Q$4+6>=$I20),"■",""),"") | R20: =IFERROR(IF(AND(R$4<=$K20,R$4+6>=$I20),"■",""),"") | S20: =IFERROR(IF(AND(S$4<=$K20,S$4+6>=$I20),"■",""),"") | T20: =IFERROR(IF(AND(T$4<=$K20,T$4+6>=$I20),"■",""),"") | U20: =IFERROR(IF(AND(U$4<=$K20,U$4+6>=$I20),"■",""),"") | V20: =IFERROR(IF(AND(V$4<=$K20,V$4+6>=$I20),"■",""),"") | W20: =IFERROR(IF(AND(W$4<=$K20,W$4+6>=$I20),"■",""),"") | X20: =IFERROR(IF(AND(X$4<=$K20,X$4+6>=$I20),"■",""),"") | ... AB20: =IFERROR(IF(AND(AB$4<=$K20,AB$4+6>=$I20),"■",""),"")
A21: 2.8 | D21: 系统参数/权限/流程配置 | E21: 任务 | F21: 必做 | G21: 实施 | H21: 项目经理 | L21: 2.1,2.7 | M21: 未开始 | N21: 0 | O21: 核心系统配置完成 | Q21: =IFERROR(IF(AND(Q$4<=$K21,Q$4+6>=$I21),"■",""),"") | R21: =IFERROR(IF(AND(R$4<=$K21,R$4+6>=$I21),"■",""),"") | S21: =IFERROR(IF(AND(S$4<=$K21,S$4+6>=$I21),"■",""),"") | T21: =IFERROR(IF(AND(T$4<=$K21,T$4+6>=$I21),"■",""),"") | U21: =IFERROR(IF(AND(U$4<=$K21,U$4+6>=$I21),"■",""),"") | V21: =IFERROR(IF(AND(V$4<=$K21,V$4+6>=$I21),"■",""),"") | W21: =IFERROR(IF(AND(W$4<=$K21,W$4+6>=$I21),"■",""),"") | X21: =IFERROR(IF(AND(X$4<=$K21,X$4+6>=$I21),"■",""),"") | ... AB21: =IFERROR(IF(AND(AB$4<=$K21,AB$4+6>=$I21),"■",""),"")
A22: 2.9 | D22: 配置项现场核对与调整 | E22: 任务 | F22: 必做 | G22: 实施 | H22: 甲方业务骨干 | L22: 2.6,2.8 | M22: 未开始 | N22: 0 | O22: 配置项核对完成 | Q22: =IFERROR(IF(AND(Q$4<=$K22,Q$4+6>=$I22),"■",""),"") | R22: =IFERROR(IF(AND(R$4<=$K22,R$4+6>=$I22),"■",""),"") | S22: =IFERROR(IF(AND(S$4<=$K22,S$4+6>=$I22),"■",""),"") | T22: =IFERROR(IF(AND(T$4<=$K22,T$4+6>=$I22),"■",""),"") | U22: =IFERROR(IF(AND(U$4<=$K22,U$4+6>=$I22),"■",""),"") | V22: =IFERROR(IF(AND(V$4<=$K22,V$4+6>=$I22),"■",""),"") | W22: =IFERROR(IF(AND(W$4<=$K22,W$4+6>=$I22),"■",""),"") | X22: =IFERROR(IF(AND(X$4<=$K22,X$4+6>=$I22),"■",""),"") | ... AB22: =IFERROR(IF(AND(AB$4<=$K22,AB$4+6>=$I22),"■",""),"")
A23: 2.10 | C23: 报告与打印 | D23: 报告模板收集与差异确认 | E23: 任务 | F23: 必做 | G23: 实施 | H23: 甲方业务骨干 | L23: 1.8 | M23: 未开始 | N23: 0 | O23: 报告模板清单/差异点 | Q23: =IFERROR(IF(AND(Q$4<=$K23,Q$4+6>=$I23),"■",""),"") | R23: =IFERROR(IF(AND(R$4<=$K23,R$4+6>=$I23),"■",""),"") | S23: =IFERROR(IF(AND(S$4<=$K23,S$4+6>=$I23),"■",""),"") | T23: =IFERROR(IF(AND(T$4<=$K23,T$4+6>=$I23),"■",""),"") | U23: =IFERROR(IF(AND(U$4<=$K23,U$4+6>=$I23),"■",""),"") | V23: =IFERROR(IF(AND(V$4<=$K23,V$4+6>=$I23),"■",""),"") | W23: =IFERROR(IF(AND(W$4<=$K23,W$4+6>=$I23),"■",""),"") | X23: =IFERROR(IF(AND(X$4<=$K23,X$4+6>=$I23),"■",""),"") | ... AB23: =IFERROR(IF(AND(AB$4<=$K23,AB$4+6>=$I23),"■",""),"")
A24: 2.11 | D24: 报告模板制作与配置 | E24: 任务 | F24: 必做 | G24: 实施 | H24: 产品/研发（按需） | L24: 2.1,2.10 | M24: 未开始 | N24: 0 | O24: 主要报告模板可用 | Q24: =IFERROR(IF(AND(Q$4<=$K24,Q$4+6>=$I24),"■",""),"") | R24: =IFERROR(IF(AND(R$4<=$K24,R$4+6>=$I24),"■",""),"") | S24: =IFERROR(IF(AND(S$4<=$K24,S$4+6>=$I24),"■",""),"") | T24: =IFERROR(IF(AND(T$4<=$K24,T$4+6>=$I24),"■",""),"") | U24: =IFERROR(IF(AND(U$4<=$K24,U$4+6>=$I24),"■",""),"") | V24: =IFERROR(IF(AND(V$4<=$K24,V$4+6>=$I24),"■",""),"") | W24: =IFERROR(IF(AND(W$4<=$K24,W$4+6>=$I24),"■",""),"") | X24: =IFERROR(IF(AND(X$4<=$K24,X$4+6>=$I24),"■",""),"") | ... AB24: =IFERROR(IF(AND(AB$4<=$K24,AB$4+6>=$I24),"■",""),"")
A25: 2.12 | D25: 标签/打印模板制作 | E25: 任务 | F25: 必做 | G25: 实施 | H25: 甲方业务骨干 | L25: 2.1,2.10 | M25: 未开始 | N25: 0 | O25: 标签/打印模板可用 | Q25: =IFERROR(IF(AND(Q$4<=$K25,Q$4+6>=$I25),"■",""),"") | R25: =IFERROR(IF(AND(R$4<=$K25,R$4+6>=$I25),"■",""),"") | S25: =IFERROR(IF(AND(S$4<=$K25,S$4+6>=$I25),"■",""),"") | T25: =IFERROR(IF(AND(T$4<=$K25,T$4+6>=$I25),"■",""),"") | U25: =IFERROR(IF(AND(U$4<=$K25,U$4+6>=$I25),"■",""),"") | V25: =IFERROR(IF(AND(V$4<=$K25,V$4+6>=$I25),"■",""),"") | W25: =IFERROR(IF(AND(W$4<=$K25,W$4+6>=$I25),"■",""),"") | X25: =IFERROR(IF(AND(X$4<=$K25,X$4+6>=$I25),"■",""),"") | ... AB25: =IFERROR(IF(AND(AB$4<=$K25,AB$4+6>=$I25),"■",""),"")
A26: 2.13 | D26: 报告/打印确认与调整 | E26: 任务 | F26: 必做 | G26: 实施 | H26: 甲方业务骨干 | L26: 2.11,2.12 | M26: 未开始 | N26: 0 | O26: 报告/打印验证通过 | Q26: =IFERROR(IF(AND(Q$4<=$K26,Q$4+6>=$I26),"■",""),"") | R26: =IFERROR(IF(AND(R$4<=$K26,R$4+6>=$I26),"■",""),"") | S26: =IFERROR(IF(AND(S$4<=$K26,S$4+6>=$I26),"■",""),"") | T26: =IFERROR(IF(AND(T$4<=$K26,T$4+6>=$I26),"■",""),"") | U26: =IFERROR(IF(AND(U$4<=$K26,U$4+6>=$I26),"■",""),"") | V26: =IFERROR(IF(AND(V$4<=$K26,V$4+6>=$I26),"■",""),"") | W26: =IFERROR(IF(AND(W$4<=$K26,W$4+6>=$I26),"■",""),"") | X26: =IFERROR(IF(AND(X$4<=$K26,X$4+6>=$I26),"■",""),"") | ... AB26: =IFERROR(IF(AND(AB$4<=$K26,AB$4+6>=$I26),"■",""),"")
A27: 2.14 | C27: 软硬件接口 | D27: 业务时序图确认 | E27: 任务 | F27: 必做 | G27: 实施 | H27: 第三方/信息科 | L27: 1.4,1.8 | M27: 未开始 | N27: 0 | O27: 接口字段和时序确认 | Q27: =IFERROR(IF(AND(Q$4<=$K27,Q$4+6>=$I27),"■",""),"") | R27: =IFERROR(IF(AND(R$4<=$K27,R$4+6>=$I27),"■",""),"") | S27: =IFERROR(IF(AND(S$4<=$K27,S$4+6>=$I27),"■",""),"") | T27: =IFERROR(IF(AND(T$4<=$K27,T$4+6>=$I27),"■",""),"") | U27: =IFERROR(IF(AND(U$4<=$K27,U$4+6>=$I27),"■",""),"") | V27: =IFERROR(IF(AND(V$4<=$K27,V$4+6>=$I27),"■",""),"") | W27: =IFERROR(IF(AND(W$4<=$K27,W$4+6>=$I27),"■",""),"") | X27: =IFERROR(IF(AND(X$4<=$K27,X$4+6>=$I27),"■",""),"") | ... AB27: =IFERROR(IF(AND(AB$4<=$K27,AB$4+6>=$I27),"■",""),"")
A28: 2.15 | D28: 接口配置/开发 | E28: 任务 | F28: 必做 | G28: 研发/实施 | H28: 产品 | L28: 2.14 | M28: 未开始 | N28: 0 | O28: 接口具备测试条件 | Q28: =IFERROR(IF(AND(Q$4<=$K28,Q$4+6>=$I28),"■",""),"") | R28: =IFERROR(IF(AND(R$4<=$K28,R$4+6>=$I28),"■",""),"") | S28: =IFERROR(IF(AND(S$4<=$K28,S$4+6>=$I28),"■",""),"") | T28: =IFERROR(IF(AND(T$4<=$K28,T$4+6>=$I28),"■",""),"") | U28: =IFERROR(IF(AND(U$4<=$K28,U$4+6>=$I28),"■",""),"") | V28: =IFERROR(IF(AND(V$4<=$K28,V$4+6>=$I28),"■",""),"") | W28: =IFERROR(IF(AND(W$4<=$K28,W$4+6>=$I28),"■",""),"") | X28: =IFERROR(IF(AND(X$4<=$K28,X$4+6>=$I28),"■",""),"") | ... AB28: =IFERROR(IF(AND(AB$4<=$K28,AB$4+6>=$I28),"■",""),"")
A29: 2.16 | D29: 单接口测试 | E29: 任务 | F29: 必做 | G29: 实施 | H29: 研发 | L29: 2.15 | M29: 未开始 | N29: 0 | O29: 单接口测试通过 | Q29: =IFERROR(IF(AND(Q$4<=$K29,Q$4+6>=$I29),"■",""),"") | R29: =IFERROR(IF(AND(R$4<=$K29,R$4+6>=$I29),"■",""),"") | S29: =IFERROR(IF(AND(S$4<=$K29,S$4+6>=$I29),"■",""),"") | T29: =IFERROR(IF(AND(T$4<=$K29,T$4+6>=$I29),"■",""),"") | U29: =IFERROR(IF(AND(U$4<=$K29,U$4+6>=$I29),"■",""),"") | V29: =IFERROR(IF(AND(V$4<=$K29,V$4+6>=$I29),"■",""),"") | W29: =IFERROR(IF(AND(W$4<=$K29,W$4+6>=$I29),"■",""),"") | X29: =IFERROR(IF(AND(X$4<=$K29,X$4+6>=$I29),"■",""),"") | ... AB29: =IFERROR(IF(AND(AB$4<=$K29,AB$4+6>=$I29),"■",""),"")
A30: 2.17 | D30: 三方接口联调 | E30: 任务 | F30: 必做 | G30: 实施 | H30: 第三方/研发/信息科 | L30: 2.16 | M30: 未开始 | N30: 0 | O30: 关键接口联调通过 | Q30: =IFERROR(IF(AND(Q$4<=$K30,Q$4+6>=$I30),"■",""),"") | R30: =IFERROR(IF(AND(R$4<=$K30,R$4+6>=$I30),"■",""),"") | S30: =IFERROR(IF(AND(S$4<=$K30,S$4+6>=$I30),"■",""),"") | T30: =IFERROR(IF(AND(T$4<=$K30,T$4+6>=$I30),"■",""),"") | U30: =IFERROR(IF(AND(U$4<=$K30,U$4+6>=$I30),"■",""),"") | V30: =IFERROR(IF(AND(V$4<=$K30,V$4+6>=$I30),"■",""),"") | W30: =IFERROR(IF(AND(W$4<=$K30,W$4+6>=$I30),"■",""),"") | X30: =IFERROR(IF(AND(X$4<=$K30,X$4+6>=$I30),"■",""),"") | ... AB30: =IFERROR(IF(AND(AB$4<=$K30,AB$4+6>=$I30),"■",""),"")
A31: 2.18 | D31: 异常场景/数据一致性验证 | E31: 任务 | F31: 必做 | G31: 实施 | H31: 第三方/研发 | L31: 2.17 | M31: 未开始 | N31: 0 | O31: 异常及边界场景验证完成 | Q31: =IFERROR(IF(AND(Q$4<=$K31,Q$4+6>=$I31),"■",""),"") | R31: =IFERROR(IF(AND(R$4<=$K31,R$4+6>=$I31),"■",""),"") | S31: =IFERROR(IF(AND(S$4<=$K31,S$4+6>=$I31),"■",""),"") | T31: =IFERROR(IF(AND(T$4<=$K31,T$4+6>=$I31),"■",""),"") | U31: =IFERROR(IF(AND(U$4<=$K31,U$4+6>=$I31),"■",""),"") | V31: =IFERROR(IF(AND(V$4<=$K31,V$4+6>=$I31),"■",""),"") | W31: =IFERROR(IF(AND(W$4<=$K31,W$4+6>=$I31),"■",""),"") | X31: =IFERROR(IF(AND(X$4<=$K31,X$4+6>=$I31),"■",""),"") | ... AB31: =IFERROR(IF(AND(AB$4<=$K31,AB$4+6>=$I31),"■",""),"")
A32: 2.19 | D32: 接口问题整改与回归 | E32: 任务 | F32: 必做 | G32: 实施 | H32: 研发/第三方 | L32: 2.18 | M32: 未开始 | N32: 0 | O32: 关键接口问题关闭 | Q32: =IFERROR(IF(AND(Q$4<=$K32,Q$4+6>=$I32),"■",""),"") | R32: =IFERROR(IF(AND(R$4<=$K32,R$4+6>=$I32),"■",""),"") | S32: =IFERROR(IF(AND(S$4<=$K32,S$4+6>=$I32),"■",""),"") | T32: =IFERROR(IF(AND(T$4<=$K32,T$4+6>=$I32),"■",""),"") | U32: =IFERROR(IF(AND(U$4<=$K32,U$4+6>=$I32),"■",""),"") | V32: =IFERROR(IF(AND(V$4<=$K32,V$4+6>=$I32),"■",""),"") | W32: =IFERROR(IF(AND(W$4<=$K32,W$4+6>=$I32),"■",""),"") | X32: =IFERROR(IF(AND(X$4<=$K32,X$4+6>=$I32),"■",""),"") | ... AB32: =IFERROR(IF(AND(AB$4<=$K32,AB$4+6>=$I32),"■",""),"")
A33: 2.20 | C33: 历史数据 | D33: 原系统数据源/迁移范围确认 | E33: 任务 | F33: 按需 | G33: 实施 | H33: 研发/甲方 | L33: 1.8 | M33: 未开始 | N33: 0 | O33: 迁移范围及数据源明确 | Q33: =IFERROR(IF(AND(Q$4<=$K33,Q$4+6>=$I33),"■",""),"") | R33: =IFERROR(IF(AND(R$4<=$K33,R$4+6>=$I33),"■",""),"") | S33: =IFERROR(IF(AND(S$4<=$K33,S$4+6>=$I33),"■",""),"") | T33: =IFERROR(IF(AND(T$4<=$K33,T$4+6>=$I33),"■",""),"") | U33: =IFERROR(IF(AND(U$4<=$K33,U$4+6>=$I33),"■",""),"") | V33: =IFERROR(IF(AND(V$4<=$K33,V$4+6>=$I33),"■",""),"") | W33: =IFERROR(IF(AND(W$4<=$K33,W$4+6>=$I33),"■",""),"") | X33: =IFERROR(IF(AND(X$4<=$K33,X$4+6>=$I33),"■",""),"") | ... AB33: =IFERROR(IF(AND(AB$4<=$K33,AB$4+6>=$I33),"■",""),"")
A34: 2.21 | D34: 字段映射/迁移规则确认 | E34: 任务 | F34: 按需 | G34: 实施 | H34: 研发 | L34: 2.20 | M34: 未开始 | N34: 0 | O34: 迁移映射规则确认 | Q34: =IFERROR(IF(AND(Q$4<=$K34,Q$4+6>=$I34),"■",""),"") | R34: =IFERROR(IF(AND(R$4<=$K34,R$4+6>=$I34),"■",""),"") | S34: =IFERROR(IF(AND(S$4<=$K34,S$4+6>=$I34),"■",""),"") | T34: =IFERROR(IF(AND(T$4<=$K34,T$4+6>=$I34),"■",""),"") | U34: =IFERROR(IF(AND(U$4<=$K34,U$4+6>=$I34),"■",""),"") | V34: =IFERROR(IF(AND(V$4<=$K34,V$4+6>=$I34),"■",""),"") | W34: =IFERROR(IF(AND(W$4<=$K34,W$4+6>=$I34),"■",""),"") | X34: =IFERROR(IF(AND(X$4<=$K34,X$4+6>=$I34),"■",""),"") | ... AB34: =IFERROR(IF(AND(AB$4<=$K34,AB$4+6>=$I34),"■",""),"")
A35: 2.22 | D35: 测试迁移 | E35: 任务 | F35: 按需 | G35: 研发 | H35: 实施 | L35: 2.1,2.21 | M35: 未开始 | N35: 0 | O35: 试迁移完成 | Q35: =IFERROR(IF(AND(Q$4<=$K35,Q$4+6>=$I35),"■",""),"") | R35: =IFERROR(IF(AND(R$4<=$K35,R$4+6>=$I35),"■",""),"") | S35: =IFERROR(IF(AND(S$4<=$K35,S$4+6>=$I35),"■",""),"") | T35: =IFERROR(IF(AND(T$4<=$K35,T$4+6>=$I35),"■",""),"") | U35: =IFERROR(IF(AND(U$4<=$K35,U$4+6>=$I35),"■",""),"") | V35: =IFERROR(IF(AND(V$4<=$K35,V$4+6>=$I35),"■",""),"") | W35: =IFERROR(IF(AND(W$4<=$K35,W$4+6>=$I35),"■",""),"") | X35: =IFERROR(IF(AND(X$4<=$K35,X$4+6>=$I35),"■",""),"") | ... AB35: =IFERROR(IF(AND(AB$4<=$K35,AB$4+6>=$I35),"■",""),"")
A36: 2.23 | D36: 迁移结果核对 | E36: 任务 | F36: 按需 | G36: 实施 | H36: 甲方/研发 | L36: 2.22 | M36: 未开始 | N36: 0 | O36: 迁移数量和关键字段核对 | Q36: =IFERROR(IF(AND(Q$4<=$K36,Q$4+6>=$I36),"■",""),"") | R36: =IFERROR(IF(AND(R$4<=$K36,R$4+6>=$I36),"■",""),"") | S36: =IFERROR(IF(AND(S$4<=$K36,S$4+6>=$I36),"■",""),"") | T36: =IFERROR(IF(AND(T$4<=$K36,T$4+6>=$I36),"■",""),"") | U36: =IFERROR(IF(AND(U$4<=$K36,U$4+6>=$I36),"■",""),"") | V36: =IFERROR(IF(AND(V$4<=$K36,V$4+6>=$I36),"■",""),"") | W36: =IFERROR(IF(AND(W$4<=$K36,W$4+6>=$I36),"■",""),"") | X36: =IFERROR(IF(AND(X$4<=$K36,X$4+6>=$I36),"■",""),"") | ... AB36: =IFERROR(IF(AND(AB$4<=$K36,AB$4+6>=$I36),"■",""),"")
A37: 2.24 | D37: 正式迁移方案/回退方案准备 | E37: 任务 | F37: 按需 | G37: 实施 | H37: 研发/项目经理 | L37: 2.23 | M37: 未开始 | N37: 0 | O37: 正式迁移及回退方案 | Q37: =IFERROR(IF(AND(Q$4<=$K37,Q$4+6>=$I37),"■",""),"") | R37: =IFERROR(IF(AND(R$4<=$K37,R$4+6>=$I37),"■",""),"") | S37: =IFERROR(IF(AND(S$4<=$K37,S$4+6>=$I37),"■",""),"") | T37: =IFERROR(IF(AND(T$4<=$K37,T$4+6>=$I37),"■",""),"") | U37: =IFERROR(IF(AND(U$4<=$K37,U$4+6>=$I37),"■",""),"") | V37: =IFERROR(IF(AND(V$4<=$K37,V$4+6>=$I37),"■",""),"") | W37: =IFERROR(IF(AND(W$4<=$K37,W$4+6>=$I37),"■",""),"") | X37: =IFERROR(IF(AND(X$4<=$K37,X$4+6>=$I37),"■",""),"") | ... AB37: =IFERROR(IF(AND(AB$4<=$K37,AB$4+6>=$I37),"■",""),"")
A38: 2.25 | C38: 测试与培训 | D38: 实施内部全流程测试 | E38: 任务 | F38: 必做 | G38: 实施 | H38: 项目经理 | L38: 2.9,2.13,2.17 | M38: 未开始 | N38: 0 | O38: 核心全流程测试完成 | Q38: =IFERROR(IF(AND(Q$4<=$K38,Q$4+6>=$I38),"■",""),"") | R38: =IFERROR(IF(AND(R$4<=$K38,R$4+6>=$I38),"■",""),"") | S38: =IFERROR(IF(AND(S$4<=$K38,S$4+6>=$I38),"■",""),"") | T38: =IFERROR(IF(AND(T$4<=$K38,T$4+6>=$I38),"■",""),"") | U38: =IFERROR(IF(AND(U$4<=$K38,U$4+6>=$I38),"■",""),"") | V38: =IFERROR(IF(AND(V$4<=$K38,V$4+6>=$I38),"■",""),"") | W38: =IFERROR(IF(AND(W$4<=$K38,W$4+6>=$I38),"■",""),"") | X38: =IFERROR(IF(AND(X$4<=$K38,X$4+6>=$I38),"■",""),"") | ... AB38: =IFERROR(IF(AND(AB$4<=$K38,AB$4+6>=$I38),"■",""),"")
A39: 2.26 | D39: 科室业务骨干联合测试 | E39: 任务 | F39: 必做 | G39: 实施 | H39: 甲方业务骨干 | L39: 2.25 | M39: 未开始 | N39: 0 | O39: 业务测试确认 | Q39: =IFERROR(IF(AND(Q$4<=$K39,Q$4+6>=$I39),"■",""),"") | R39: =IFERROR(IF(AND(R$4<=$K39,R$4+6>=$I39),"■",""),"") | S39: =IFERROR(IF(AND(S$4<=$K39,S$4+6>=$I39),"■",""),"") | T39: =IFERROR(IF(AND(T$4<=$K39,T$4+6>=$I39),"■",""),"") | U39: =IFERROR(IF(AND(U$4<=$K39,U$4+6>=$I39),"■",""),"") | V39: =IFERROR(IF(AND(V$4<=$K39,V$4+6>=$I39),"■",""),"") | W39: =IFERROR(IF(AND(W$4<=$K39,W$4+6>=$I39),"■",""),"") | X39: =IFERROR(IF(AND(X$4<=$K39,X$4+6>=$I39),"■",""),"") | ... AB39: =IFERROR(IF(AND(AB$4<=$K39,AB$4+6>=$I39),"■",""),"")
A40: 2.27 | D40: 测试问题整改与回归 | E40: 任务 | F40: 必做 | G40: 实施 | H40: 产品/研发 | L40: 2.26 | M40: 未开始 | N40: 0 | O40: 阻塞性问题关闭 | Q40: =IFERROR(IF(AND(Q$4<=$K40,Q$4+6>=$I40),"■",""),"") | R40: =IFERROR(IF(AND(R$4<=$K40,R$4+6>=$I40),"■",""),"") | S40: =IFERROR(IF(AND(S$4<=$K40,S$4+6>=$I40),"■",""),"") | T40: =IFERROR(IF(AND(T$4<=$K40,T$4+6>=$I40),"■",""),"") | U40: =IFERROR(IF(AND(U$4<=$K40,U$4+6>=$I40),"■",""),"") | V40: =IFERROR(IF(AND(V$4<=$K40,V$4+6>=$I40),"■",""),"") | W40: =IFERROR(IF(AND(W$4<=$K40,W$4+6>=$I40),"■",""),"") | X40: =IFERROR(IF(AND(X$4<=$K40,X$4+6>=$I40),"■",""),"") | ... AB40: =IFERROR(IF(AND(AB$4<=$K40,AB$4+6>=$I40),"■",""),"")
...

Sheet 关键里程碑
A1: SOP阶段关键里程碑
A3: 序号 | B3: SOP阶段 | C3: 关键里程碑 | D3: 计划日期 | E3: 主责 | F3: 进入条件 | G3: 输出/确认 | H3: 状态
A4: M01 | B4: 事前准备 | C4: 进场准入评审 | D4: =项目实施计划!K12 -> 0 | E4: 项目经理 | F4: 接口、环境、人员、计划等关键前置条件满足 | G4: 进场准入结论 | H4: 未开始
A5: M02 | B5: 事前准备 | C5: 项目启动会 | D5: =项目实施计划!K13 -> 0 | E5: 项目经理 | F5: 准入评审通过 | G5: 项目启动会议纪要 | H5: 未开始
A6: M03 | B6: 试行验证 | C6: 上线条件评估 | D6: =项目实施计划!K47 -> 0 | E6: 实施/项目经理 | F6: 试行完成、阻塞性问题关闭 | G6: 上线条件评估表 | H6: 未开始
A7: M04 | B7: 上线切换 | C7: 正式上线 | D7: =项目实施计划!K51 -> 0 | E7: 项目经理 | F7: 上线条件评估通过、切换方案确认 | G7: 上线确认单 | H7: 未开始
A8: M05 | B8: 验收交付 | C8: 验收条件确认 | D8: =项目实施计划!K57 -> 0 | E8: 项目经理 | F8: 上线稳定、资料/遗留问题基本完成 | G8: 具备验收条件 | H8: 未开始
A9: M06 | B9: 验收交付 | C9: 项目验收会议 | D9: =项目实施计划!K58 -> 0 | E9: 项目经理 | F9: 验收条件确认通过 | G9: 项目验收报告/会议纪要 | H9: 未开始
A10: M07 | B10: 验收交付 | C10: 项目资料移交 | D10: =项目实施计划!K60 -> 0 | E10: 项目经理 | F10: 验收整改完成 | G10: 项目交付清单 | H10: 未开始

Sheet 使用说明
A1: 项目实施计划模板使用说明
A3: 01 | B3: 阶段逻辑 | C3: 阶段严格按SOP划分：事前准备 → 实施执行 → 试行验证 → 上线切换 → 验收交付。
A4: 02 | B4: 任务逻辑 | C4: 每个阶段内部使用实际实施任务，不再用SOP条款直接充当项目任务。
A5: 03 | B5: 并行推进 | C5: 实施执行阶段内，环境、基础数据、系统配置、报告模板、接口、历史数据可并行推进。
A6: 04 | B6: 项目启动会 | C6: 进场准入评审通过后召开，至少甲乙双方参加，形成《项目启动会议纪要》。
A7: 05 | B7: 环境搭建 | C7: 系统环境搭建由运维主责、实施协同。
A8: 06 | B8: 上线前核验 | C8: 统一归入试行验证阶段的“上线条件评估”，由实施主责、项目经理确认。
A9: 07 | B9: 历史数据 | C9: 旧系统替换时启用；新上线无迁移时将相关任务标记为“不适用”。
A10: 08 | B10: 计划更新 | C10: 修改F2计划开始日期后，计划日期、目标上线、验收日期和甘特图自动联动。
A11: 09 | B11: 周会维护 | C11: 每周只更新状态、完成率、当前问题/备注；基线日期确需调整时记录延期原因。
